Workbook
Name BDM_Name: Lookup!$U$2:$U$17
Name Billing_Month: Table3[Billing Month]
Name Billing_Month: Table3[Billing Month]
Name Billing_Status: Table4[Billing Status]
Name Billing_Status: Table4[Billing Status]
Name Deal_Probability: Table6[Deal Probability]
Name Deal_Probability: Table6[Deal Probability]
Name Deal_Status: Table2[Deal Status]
Name Deal_Status: Table2[Deal Status]
Name Deal_Type: Table7[Deal Type]
Name Deal_Type: Table7[Deal Type]
Name LOB_INPUT: Table1[LOB INPUT]
Name LOB_INPUT: Table1[LOB INPUT]
Name Sales_Vertical: Table8[Sales Vertical]
Name Sales_Vertical: Table8[Sales Vertical]
Name Source: Table5[Source]
Name Source: Table5[Source]

Sheet Lookup
A1: LOB INPUT | C1: Deal Status | E1: Billing Month | G1: Billing Status | I1: Source | K1: Deal Probability | M1: Deal Type | O1: Sales Vertical | U1: BDM Name
A2: ITSS Cisco LoB | C2: Commit | E2: 46113 | F2: FY 27 Q1 | G2: Yes | I2: Backlog Deal | K2: High | M2: Product | O2: Mining Indust&Health | Q2: Focus Needed | S2: New Engagement | U2: David Ramorola
A3: ITSS Dell Technologies LoB | C3: Upside | E3: 46143 | F3: FY 27 Q1 | G3: No | I3: Committed Pipe Deal | K3: Medium | M3: Software / Licence | O3: Corporate | Q3: Priority | S3: Pipeline | U3: Hein Botha
A4: ITSS Financing Solutions | E4: 46174 | F4: FY 27 Q1 | I4: Upside Deal | K4: Low | M4: OEM Service | O4: Public | Q4: Telkom R40m | U4: Johan Taljaard
A5: ITSS HPE LoB | E5: 46204 | F5: FY 27 Q2 | O5: FSI & Retail | Q5: Deals moved | U5: Lawrence Lethuba
A6: ITSS Huawei LoB | E6: 46235 | F6: FY 27 Q2 | O6: Other | Q6: Additional requirement | U6: Lebogang Ziqubu
A7: ITSS Oracle LoB | E7: 46266 | F7: FY 27 Q2 | O7: SAP Backlog / Invoiced | Q7: 1700 | U7: Mason Hlongwane
A8: ITSS Smart Office Connexion LoB | E8: 46296 | F8: FY 27 Q3 | Q8: R1700 upside | U8: Nowell Duze
A9: ITSS Tech Management | E9: 46327 | F9: FY 27 Q3 | Q9: R300m JB | U9: Ntokozo Maseko
A10: ITSS Technology Integration LoB | E10: 46357 | F10: FY 27 Q3 | U10: Olden Pieterse
A11: ITSS Workspace LoB | E11: 46388 | F11: FY 27 Q4 | U11: Paul van Rooyen
A12: Central BDM | E12: 46419 | F12: FY 27 Q4 | U12: Roan van Nieuwenhuizen
E13: 46447 | F13: FY 27 Q4 | U13: Sean Royds
E14: 46478 | F14: FY 28 Q1 | U14: Wandile Dlamini
E15: 46508 | F15: FY 28 Q1 | U15: Wes Beck
E16: 46539 | F16: FY 28 Q1 | U16: Wimpie Pieterse

Sheet Current Cadence
A1: LOB INPUT
D2: Totals | E2: =SUM(E4:E497) -> 9.9886404e+08 | F2: =SUM(F4:F161985) -> 7.5046369e+08 | G2: =SUM(G4:G161985) -> 77605851
A3: LOB INPUT | B3: Customer Name | C3: Sales Vertical | D3: OPP Number | E3: Gross Revenue | F3: Expected Net Revenue | G3: GP Value | H3: GP % | I3: Deal Status | J3: Billing Month | K3: FY Qrt list | L3: Billing Status | M3: Source | N3: Deal Probability | O3: Extra Notes | P3: Presales Name | Q3: LOB / BDM Name | R3: Deal Type | S3: Update | T3: Medium high chase
A4: ITSS Cisco LoB | B4: South African Revenue Services | C4: Public | D4: OPP145398 | E4: 2.4910934e+08 | F4: 2.4910934e+08 | G4: 19928747 | H4: 0.08 | I4: Upside | J4: 46447 | K4: FY 27 Q4 | L4: No | M4: Upside Deal | N4: Low | P4: David Ramorola | Q4: Wimpie Pieterse | R4: Product | S4: RFP - TowerD Secure Access, 1000Eyes, Meraki switches(5years)
A5: ITSS Cisco LoB | B5: South African Social Agency (SASSA) | C5: Public | D5: OPP146677 | E5: 1.235666e+08 | F5: 1.235666e+08 | G5: 6178330.2 | H5: 0.05 | I5: Upside | J5: 46447 | K5: FY 27 Q4 | L5: No | M5: Upside Deal | N5: Low | P5: David Ramorola | Q5: Wimpie Pieterse | R5: Product | S5: RFQ - Meraki SD-Wan + Security (Switches and Sec-SUITE)
A6: ITSS Cisco LoB | B6: The Spar Group Ltd | C6: FSI & Retail | D6: OPP136919 | E6: 38123456 | F6: 4574814.7 | G6: 4574814.7 | H6: 0.12 | I6: Upside | J6: 46174 | K6: FY 27 Q1 | L6: No | M6: Upside Deal | N6: High | O6: checked | P6: Roan van Nieuwenhuizen | Q6: Wimpie Pieterse | R6: Software / Licence | S6: Need to move Licenses to another ORG to reduce the License limit. This is before we can create Cisco Meraki EA
A7: ITSS Cisco LoB | B7: Telkom Consumer | C7: Mining Indust&Health | D7: OPP133098 | E7: 33825197 | F7: 1691259.9 | G7: 1691259.9 | H7: 0.05 | I7: Commit | J7: 46174 | K7: FY 27 Q1 | L7: No | M7: Backlog Deal | N7: High | O7: checked | P7: johan Taljaard | Q7: Wimpie Pieterse | R7: OEM Service | S7: SFC Annual Payment
A8: ITSS Cisco LoB | B8: Discovery Central Services (Pty) Ltd | C8: FSI & Retail | D8: OPP147096 | E8: 30614619 | F8: 30614619 | G8: 1530730.9 | H8: 0.05 | I8: Upside | J8: 46235 | K8: FY 27 Q2 | L8: No | M8: Upside Deal | N8: Low | O8: checked | P8: Paul van Rooyen | Q8: Wimpie Pieterse | R8: Product | S8: RFQ - Network refresh
A9: ITSS Cisco LoB | B9: Telkom ISP | C9: Mining Indust&Health | D9: OPP147364 | E9: 28723558 | F9: 2872355.8 | G9: 2872355.8 | H9: 0.1 | I9: Upside | J9: 46327 | K9: FY 27 Q3 | L9: No | M9: Upside Deal | N9: Medium | O9: checked | P9: Johan Taljaard | Q9: Wimpie Pieterse | R9: Software / Licence | S9: DDOS
A10: ITSS Cisco LoB | B10: Openserve | C10: Mining Indust&Health | D10: OPP145768 | E10: 21938053 | F10: 1096902.6 | G10: 1096902.6 | H10: 0.05 | I10: Upside | J10: 46327 | K10: FY 27 Q3 | L10: No | M10: Upside Deal | N10: Medium | O10: checked | P10: Johan Taljaard | Q10: Wimpie Pieterse | R10: Product | S10: FW budget prep 10 x FW's + secure workload
A11: ITSS Cisco LoB | B11: Telkom Consumer | C11: Mining Indust&Health | D11: OPP147259 | E11: 21938052 | F11: 21938052 | G11: 2193805.2 | H11: 0.1 | I11: Upside | J11: 46327 | K11: FY 27 Q3 | L11: No | M11: Upside Deal | N11: Low | O11: checked | P11: Johan Taljaard | Q11: Wimpie Pieterse | R11: Product | S11: Telkom BCX ACI FW Replace 67 Contexts
A12: ITSS Cisco LoB | B12: The Standard Bank of South Africa | C12: FSI & Retail | D12: OPP13777 | E12: 17211644 | F12: 1721164.4 | G12: 1721164.4 | H12: 0.1 | I12: Commit | J12: 46478 | L12: No | M12: Backlog Deal | N12: High | O12: Checked | P12: Paul van Rooyen | Q12: Wimpie Pieterse | R12: Software / Licence | S12: APP-D EA Renewal
A13: ITSS Cisco LoB | B13: Telkom Consumer | C13: Mining Indust&Health | D13: OPP135119/01 | E13: 15799289 | F13: 15799289 | G13: 1421936 | H13: 0.09 | I13: Upside | J13: 46327 | K13: FY 27 Q3 | L13: No | M13: Upside Deal | N13: Medium | O13: checked | P13: Johan Taljaard | Q13: Wimpie Pieterse | R13: Product | S13: EDD 154 days after order placement - Nutanix Expansion Value updated, Busy repricing will be resubmitted to Telkom
A14: ITSS Cisco LoB | B14: Openserve | C14: Mining Indust&Health | D14: OPP141512/01 | E14: 14895000 | F14: 14895000 | G14: 1489500 | H14: 0.1 | I14: Upside | J14: 46327 | K14: FY 27 Q3 | L14: No | M14: Upside Deal | N14: Medium | O14: checked | P14: Johan Taljaard | Q14: Wimpie Pieterse | R14: Product | S14: International POPS - Telkom wants eq for evaluation before project go ahead
A15: ITSS Cisco LoB | B15: SANBS | C15: Public | D15: OPP146783 | E15: 14433451 | F15: 721672.55 | G15: 721672.55 | H15: 0.05 | I15: Upside | J15: 46296 | K15: FY 27 Q3 | L15: No | M15: Upside Deal | N15: Low | O15: Checked | P15: Wandile Dlamini | Q15: Wimpie Pieterse | R15: OEM Service | S15: Current support expires at the end of Sep-2026
A16: ITSS Cisco LoB | B16: Nedbank Limited | C16: FSI & Retail | D16: OPP147252 | E16: 14378595 | F16: 862715.69 | G16: 862715.69 | H16: 0.06 | I16: Upside | J16: 46266 | K16: FY 27 Q2 | L16: No | M16: Upside Deal | N16: Low | P16: Sean Royds | Q16: Wimpie Pieterse | R16: Product | S16: Budgetsry for Jac-Lou Wireless Guest Portal Business Case
A17: ITSS Cisco LoB | B17: Openserve (Pty) Ltd | C17: Mining Indust&Health | D17: OPP145588 | E17: 13312345 | F17: 665617.25 | G17: 665617.25 | H17: 0.05 | I17: Upside | J17: 46174 | K17: FY 27 Q1 | L17: No | M17: Upside Deal | N17: High | O17: checked | P17: Johan Taljaard | Q17: Wimpie Pieterse | R17: OEM Service | S17: Opernserve Sweep Year 1 of 3
A18: ITSS Cisco LoB | B18: Woolworths (Pty) Limited | C18: FSI & Retail | D18: OPP128359 | E18: 13294957 | F18: 13294957 | G18: 1329495.7 | H18: 0.1 | I18: Commit | J18: 46266 | K18: FY 27 Q2 | L18: No | M18: Committed Pipe Deal | N18: High | P18: Olden Pieterse | Q18: Wimpie Pieterse | R18: Product | S18: Operate UC waiting for customer signature on contract
A19: ITSS Cisco LoB | B19: Telkom | C19: Mining Indust&Health | D19: OPP135119 | E19: 13162789 | F19: 13162789 | G19: 1316278.9 | H19: 0.1 | I19: Upside | J19: 46327 | K19: FY 27 Q3 | L19: No | M19: Upside Deal | N19: Medium | O19: checked | P19: Johan Taljaard | Q19: Wimpie Pieterse | R19: Product | S19: Telkom Nutanix expansion
A20: ITSS Cisco LoB | B20: Telkom Consumer | C20: Mining Indust&Health | D20: OPP142649/02 | E20: 13140597 | F20: 13140597 | G20: 1182653.7 | H20: 0.09 | I20: Upside | J20: 46327 | K20: FY 27 Q3 | L20: No | M20: Upside Deal | N20: Medium | O20: checked | P20: Johan Taljaard | Q20: Wimpie Pieterse | R20: Product | S20: EDD 42 days after order placement - EoL Switches & line cards
A21: ITSS Cisco LoB | B21: Openserve | C21: Mining Indust&Health | D21: OPP148548 | E21: 12449770 | F21: 12449770 | G21: =F21*H21 -> 1244977 | H21: 0.1 | I21: Upside | J21: 46327 | K21: =IF(J21="","",_xlfn.XLOOKUP(J21,Lookup!E:E,Lookup!F:F)) -> FY 27 Q3 | L21: No | M21: Upside Deal | N21: Medium | O21: OPP148548 Openserve SPINE Switches - Tygerburg & Core | P21: Johan Taljaard | Q21: Wimpie Pieterse | R21: Product
A22: ITSS Cisco LoB | B22: Air Traffic and Navigation ServicesCompany Limited | C22: Public | D22: OPP123907 | E22: 12000000 | F22: 12000000 | G22: 375152 | H22: 0.1 | I22: Upside | J22: 46447 | K22: FY 27 Q4 | L22: No | M22: Upside Deal | N22: Low | O22: Checked | P22: Wandile Dlamini | Q22: Wimpie Pieterse | R22: Product | S22: Ongoing Tender - Waiting for award for more than a year
A23: ITSS Cisco LoB | B23: Telkom SA SOC Limited | C23: Mining Indust&Health | D23: OPP122332/04 | E23: 11391262 | F23: 569563.1 | G23: 569563.1 | H23: 0.05 | I23: Commit | J23: 46204 | K23: FY 27 Q2 | L23: No | M23: Backlog Deal | N23: High | O23: checked | P23: johan Taljaard | Q23: Wimpie Pieterse | R23: OEM Service | S23: APP-D EA Year 2/3
A24: ITSS Cisco LoB | B24: Western Cape Government Health | C24: Public | D24: OPP140607 | E24: 10854175 | F24: 10854175 | G24: 542708.75 | H24: 0.05 | I24: Upside | J24: 46296 | K24: FY 27 Q3 | L24: No | M24: Upside Deal | N24: Low | O24: Checked | P24: Wandile Dlamini | Q24: Wimpie Pieterse | R24: Product | S24: EDD 45 days - LAN refresh - customer asked for bid evaluation extension until 01-Aug-2026
A25: ITSS Cisco LoB | B25: Telkom Consumer | C25: Mining Indust&Health | D25: OPP142649/01 | E25: 10827243 | F25: 10827243 | G25: 974451.85 | H25: 0.09 | I25: Upside | J25: 46327 | K25: FY 27 Q3 | L25: No | M25: Upside Deal | N25: Medium | O25: checked | P25: Johan Taljaard | Q25: Wimpie Pieterse | R25: Product | S25: EDD 58 days after order placement - Line Cards
A26: ITSS Cisco LoB | B26: Tiger Brands | C26: FSI & Retail | D26: OPP138466 | E26: 10753040 | F26: 860243.23 | G26: 860243.23 | H26: 0.08 | I26: Upside | J26: 46204 | K26: FY 27 Q2 | L26: No | M26: Upside Deal | N26: Low | O26: Checked | P26: Nowell Duze | Q26: Wimpie Pieterse | R26: Product | S26: Quote refreshed on the 18th of May. Vblock DC switches
A27: ITSS Cisco LoB | B27: Pep A Division Of Pepkor Trading (PTd | C27: Corporate | D27: OPP146179 | E27: 8123456 | F27: 974814.72 | G27: 974814.72 | H27: 0.12 | I27: Upside | J27: 46327 | K27: FY 27 Q3 | L27: No | M27: Upside Deal | N27: High | O27: checked | P27: Roan van Nieuwenhuizen | Q27: Wimpie Pieterse | R27: Software / Licence | S27: Working on a 3 and 5 year EA Renewal. Customer will release an RFQ, EA expiring in Nov 2026
A28: ITSS Cisco LoB | B28: Durban ICC | C28: Public | D28: OPP145736 | E28: 7845333 | F28: 7845333 | G28: 392266.65 | H28: 0.05 | I28: Upside | J28: 46266 | K28: FY 27 Q2 | L28: No | M28: Upside Deal | N28: Medium | O28: Checked | P28: Wandile Dlamini | Q28: Wimpie Pieterse | R28: Product | S28: EDD 100 days - Wireless refresh
A29: ITSS Cisco LoB | B29: Volkswagen Group Africa (Pty) Ltd | C29: Corporate | D29: OPP148038 | E29: 7461453 | F29: 7461453 | G29: 746145.3 | H29: 0.1 | I29: Upside | J29: 46235 | K29: FY 27 Q2 | L29: No | M29: Upside Deal | N29: Low | P29: Roan van Nieuwenhuizen | Q29: Wimpie Pieterse | R29: Product | S29: Respond to RFQ for Kariga Firewals
A30: ITSS Cisco LoB | B30: Electoral Commission of SouthAfrica Iec | C30: Public | D30: OPP147418 | E30: 7405205 | F30: 7405205 | G30: 740520.5 | H30: 0.1 | I30: Upside | J30: 46266 | K30: FY 27 Q2 | L30: No | M30: Upside Deal | N30: Low | P30: Roan van Nieuwenhuizen | Q30: Wimpie Pieterse | R30: Product | S30: IEC Wireless Solution
A31: ITSS Cisco LoB | B31: Electoral Commission of SouthAfrica Iec | C31: Public | D31: OPP139758 | E31: 7056976.2 | F31: 1372145.7 | G31: 705697.62 | H31: 0.1 | I31: Commit | J31: 46235 | K31: FY 27 Q2 | L31: No | M31: Backlog Deal | N31: High | O31: Checked | P31: David Ramorola | Q31: Wimpie Pieterse | R31: Software / Licence | S31: Contract start date 1 August
A32: ITSS Cisco LoB | B32: Pep A Division Of Pepkor Trading (PTd | C32: Corporate | D32: OPP141566 | E32: 6991803.2 | F32: 6991803.2 | G32: 489426.23 | H32: 0.07 | I32: Upside | J32: 46419 | K32: FY 27 Q4 | L32: No | M32: Upside Deal | N32: Medium | O32: checked | P32: Paul van Rooyen | Q32: Wimpie Pieterse | R32: Product | S32: Capfin Catalyst refresh
A33: ITSS Cisco LoB | B33: Nedbank Limited | C33: FSI & Retail | D33: OPP147043 | E33: 5790700.2 | F33: 5790700.2 | G33: 347442.01 | H33: 0.06 | I33: Commit | J33: 46204 | K33: FY 27 Q2 | L33: No | M33: Backlog Deal | N33: High | P33: Sean Royds | Q33: Wimpie Pieterse | R33: Product | S33: EDD 16 July; Shuaib will push to add to NBV Jul signoff
A34: ITSS Cisco LoB | B34: Volkswagen Group Africa (Pty) Ltd | C34: Corporate | D34: OPP146486 | E34: 5751314 | F34: 5751314 | G34: 575131.4 | H34: 0.1 | I34: Upside | J34: 46235 | K34: FY 27 Q2 | L34: No | M34: Upside Deal | N34: Low | P34: Roan van Nieuwenhuizen | Q34: Wimpie Pieterse | R34: Product | S34: Provide Security EA Proposal
A35: ITSS Cisco LoB | B35: Capitec Bank Limited | C35: FSI & Retail | D35: OPP089485 | E35: 5699203 | F35: 159577.68 | G35: 159577.68 | H35: 0.028 | I35: Commit | J35: 46327 | K35: FY 27 Q3 | L35: No | M35: Backlog Deal | N35: High | O35: checked | P35: Paul van Rooyen | Q35: Wimpie Pieterse | R35: Software / Licence | S35: SDWAN EA Annual payment
A36: ITSS Cisco LoB | B36: Tiger Brands | C36: FSI & Retail | D36: OPP146660 | E36: 5301769.3 | F36: 5301769.3 | G36: 424141.55 | H36: 0.08 | I36: Upside | J36: 46204 | K36: FY 27 Q2 | L36: No | M36: Upside Deal | N36: Low | O36: Checked | P36: Nowell Duze | Q36: Wimpie Pieterse | R36: Product | S36: Bafo Pricing submitted on the 22nd May 2026
A37: ITSS Cisco LoB | B37: Momentum Metropolitan Life Ltd Metropolitan | C37: FSI & Retail | D37: OPP142558 | E37: 5238762.6 | F37: 5238762.6 | G37: 628651.51 | H37: 0.12 | I37: Commit | J37: 46143 | K37: FY 27 Q1 | L37: Yes | M37: Backlog Deal | N37: High | O37: Checked | P37: Wandile Dlamini | Q37: Wimpie Pieterse | R37: Product | S37: EDD 196 days after order placement - New Rivonia branch
A38: ITSS Cisco LoB | B38: PepsiCo South Africa (Pty) Ltd | C38: Corporate | D38: OPP144981 | E38: 4973229.5 | F38: 4973229.5 | G38: 248661 | H38: 0.045 | I38: Upside | J38: 46235 | K38: =IF(J38="","",_xlfn.XLOOKUP(J38,Lookup!E:E,Lookup!F:F)) -> FY 27 Q2 | L38: No | M38: Upside Deal | N38: Medium | P38: Olden Pieterse | Q38: Wimpie Pieterse | R38: Product | S38: Submitted Quote : 28/5/2026
A39: ITSS Cisco LoB | B39: Sanlam Life Insurance Limited | C39: FSI & Retail | D39: OPP137867 | E39: 4963898 | F39: 4963898 | G39: 496389.8 | H39: 0.1 | I39: Upside | J39: 46235 | K39: FY 27 Q2 | L39: No | M39: Upside Deal | N39: Medium | P39: Sean Royds | Q39: Wimpie Pieterse | R39: Product | S39: EDD 56 days after order placement - Assupol SD-WAN Routers
A40: ITSS Cisco LoB | B40: Sanlam Life Insurance Limited | C40: FSI & Retail | D40: OPP145901 | E40: 4249038.3 | F40: 4249038.3 | G40: 424903.83 | H40: 0.1 | I40: Commit | J40: 46327 | K40: FY 27 Q3 | L40: No | M40: Backlog Deal | N40: High | P40: Sean Royds | Q40: Wimpie Pieterse | R40: Product | S40: EDD 3 June 2026
...

Sheet Add to Cadence
A1: LOB INPUT
D2: Totals | E2: =SUM(E4:E161996) -> 0 | F2: =SUM(F4:F161996) -> 0 | G2: =SUM(G4:G161996) -> 0
A3: LOB INPUT | B3: Customer Name | C3: Sales Vertical | D3: OPP Number | E3: Gross Revenue | F3: Expected Net Revenue | G3: GP Value | H3: GP % | I3: Deal Status | J3: Billing Month | K3: FY Qrt list | L3: Billing Status | M3: Source | N3: Deal Probability | O3: Extra Notes | P3: Presales Name | Q3: LOB / BDM Name | R3: Deal Type | S3: Update | T3: Medium high chase
A4: ITSS Cisco LoB | B4: ABB South Africa (Pty) Ltd | C4: Corporate | D4: OPP148431 | E4: R 421 128,38 | F4: R 421 128,39 | H4: 0.1 | I4: Upside | J4: 46266 | L4: No | M4: Upside Deal | N4: Medium | P4: Mason Hlongwane | Q4: Wes Beck | R4: Software / Licence | S4: waiting for response
K16: =IF(J16="","",_xlfn.XLOOKUP(J16,Lookup!E:E,Lookup!F:F))
K17: =IF(J17="","",_xlfn.XLOOKUP(J17,Lookup!E:E,Lookup!F:F))
K18: =IF(J18="","",_xlfn.XLOOKUP(J18,Lookup!E:E,Lookup!F:F))
K19: =IF(J19="","",_xlfn.XLOOKUP(J19,Lookup!E:E,Lookup!F:F))
K20: =IF(J20="","",_xlfn.XLOOKUP(J20,Lookup!E:E,Lookup!F:F))
K21: =IF(J21="","",_xlfn.XLOOKUP(J21,Lookup!E:E,Lookup!F:F))
K22: =IF(J22="","",_xlfn.XLOOKUP(J22,Lookup!E:E,Lookup!F:F))
K23: =IF(J23="","",_xlfn.XLOOKUP(J23,Lookup!E:E,Lookup!F:F))
K24: =IF(J24="","",_xlfn.XLOOKUP(J24,Lookup!E:E,Lookup!F:F))
K25: =IF(J25="","",_xlfn.XLOOKUP(J25,Lookup!E:E,Lookup!F:F))
K26: =IF(J26="","",_xlfn.XLOOKUP(J26,Lookup!E:E,Lookup!F:F))
K27: =IF(J27="","",_xlfn.XLOOKUP(J27,Lookup!E:E,Lookup!F:F))
... K58: =IF(J58="","",_xlfn.XLOOKUP(J58,Lookup!E:E,Lookup!F:F))

Sheet SFDCVerify
B1: LOB INPUT | C1: Customer Name | D1: Sales Vertical | E1: OPP Number | F1: Gross Revenue | G1: Expected Net Revenue | H1: GP Value | I1: GP % | J1: Deal Status | K1: Billing Month | L1: FY Qrt list | M1: Billing Status | N1: Source | O1: Deal Probability | P1: Extra Notes | Q1: Presales Name
B2: ITSS Cisco Products | C2: South African Social Agency (SASSA) | D2: Lerato Maja | E2: OPP146677/06 | F2: 144390113 | H2: 7219505.7 | I2: 0.05 | J2: Upside | K2: 2029/10/01 | M2: No | N2: Proposal Submitted | O2: Low | Q2: David Ramorola
A3: Please remove this is not a ITSS Cisco OPP | B3: ITSS Cisco Products | C3: Alexander Forbes Group Services (PTY)LTD | D3: Nonhlanhla Chitura | E3: OPP138612 | F3: 75000000 | H3: 11250000 | I3: 0.15 | J3: Upside | K3: 2029/10/01 | M3: No | N3: Opportunity Created | O3: Medium
B4: ITSS Cisco Products | C4: Pep A Division Of Pepkor Trading (PTd | D4: Freddy Abrahams | E4: OPP145464 | F4: 67361615 | H4: 4715313.1 | I4: 0.07 | J4: Upside | K4: 2027/01/01 | M4: No | N4: Quote Created | O4: Low | Q4: Paul van Rooyen
B5: ITSS Cisco Products | C5: Eskom Holdings (SOC) Ltd | D5: Thuli Kgabo | E5: OPP114025/01 | F5: 65000000 | H5: 7800000 | I5: 0.12 | J5: Upside | K5: 2029/10/01 | M5: No | N5: Lead Generated | O5: Low
B6: ITSS Cisco Products | C6: Nedbank Limited | D6: Johan Marais | E6: OPP146707 | F6: 52689875 | H6: 1580696.2 | I6: 0.03 | J6: Upside | K6: 2027/02/01 | M6: No | N6: Opportunity Created | O6: Low
B7: ITSS Cisco Products | C7: Openserve (Pty) Ltd | D7: Estelle Van der Walt | E7: OPP141512/01 | F7: 36769778 | H7: 3676977.8 | I7: 0.1 | J7: Upside | K7: 2026/09/01 | M7: No | N7: Quote Created | O7: Low | Q7: Johan Taljaard
B8: ITSS Cisco Products | C8: Airports Company South Africa (SOC) | D8: .Paballo Lehloma | E8: OPP143531/01 | F8: 34092194 | H8: 3409219.4 | I8: 0.1 | J8: Upside | K8: 2026/08/01 | M8: No | N8: Quote Created | O8: Low | Q8: Johan Taljaard; Wandile Dlamini; John Killian
B9: ITSS Cisco Products | C9: Openserve (Pty) Ltd | D9: Estelle Van der Walt | E9: OPP148228/01 | F9: 30000000 | H9: 3000000 | I9: 0.1 | J9: Upside | K9: 2026/09/01 | M9: No | N9: Opportunity Created | O9: Low
A10: Valid Opp Low win probeblity | B10: ITSS Cisco Products | C10: Telkom Consumer | D10: Bongani Nhlanzi | E10: OPP134434 | F10: 29034060 | H10: 2903406 | I10: 0.1 | J10: Upside | K10: 2026/09/01 | M10: No | N10: Proposal Submitted | O10: Low | Q10: Johan Taljaard
B11: ITSS Cisco Products | C11: State Information Technology AgencyLtd | D11: John Croone | E11: OPP139035 | F11: 25012131 | H11: 2501213.1 | I11: 0.1 | J11: Upside | K11: 2026/10/01 | M11: No | N11: Proposal Submitted | O11: Medium | Q11: David Ramorola
B12: ITSS Cisco Products | C12: Nedbank Limited | D12: Johan Marais | E12: OPP132268 | F12: 24713987 | H12: 2471398.7 | I12: 0.1 | J12: Upside | K12: 2027/03/01 | M12: No | N12: Proposal Created | O12: Medium | Q12: Sean Royds
A13: Please remove, Already in cadence | B13: ITSS Cisco Products | C13: Openserve (Pty) Ltd | D13: Estelle Van der Walt | E13: OPP145768/01 | F13: 21938053 | H13: 2193805.3 | I13: 0.1 | J13: Upside | K13: 2026/08/01 | M13: No | N13: Quote Created | O13: Low | Q13: Johan Taljaard
B14: ITSS Cisco Products | C14: Nedbank Limited | D14: Johan Marais | E14: OPP125805 | F14: 19863301 | H14: 1191798 | I14: 0.06 | J14: Upside | K14: 2026/06/01 | M14: No | N14: Opportunity Qualified | O14: Low | Q14: Sean Royds
B15: ITSS Cisco Products | C15: Mr Price Group Limited | D15: Dinesh Maharaj | E15: OPP139787 | F15: 18602487 | H15: 744099.46 | I15: 0.04 | J15: Upside | K15: 2026/08/01 | M15: No | N15: Awaiting Customer Decision | O15: Low | Q15: Roan van Nieuwenhuizen
B16: ITSS Cisco Products | C16: Human Settlements | D16: Zodwa Ntshangase | E16: OPP140895/01 | F16: 17503044 | H16: 875152.18 | I16: 0.05 | J16: Upside | K16: 2026/09/01 | M16: No | N16: Quote Created | O16: Low | Q16: David Ramorola; Hanno Oosthuisen
B17: ITSS Cisco Products | C17: Life Healthcare Group (Pty) Ltd | D17: Melissa Cloete | E17: OPP144429 | F17: 15072048 | H17: 1808645.8 | I17: 0.12 | J17: Upside | K17: 2026/09/01 | M17: No | N17: Proposal Created | O17: Low | Q17: Wandile Dlamini
B18: ITSS Cisco Products | C18: AVI Financial Services (Pty) Ltd | D18: Andre Erasmus | E18: OPP125425/04 | F18: 15000000 | H18: 750000 | I18: 0.05 | J18: Upside | K18: 2027/11/01 | M18: No | N18: Products identified | O18: Low
B19: ITSS Cisco Products | C19: South African Reserve Bank | D19: .Paballo Lehloma | E19: OPP144770/01 | F19: 15000000 | H19: 1050000 | I19: 0.07 | J19: Upside | K19: 2027/03/01 | M19: No | N19: Products identified | O19: Medium
A20: Valid Opp Low win probeblity | B20: ITSS Cisco Products | C20: Telkom Consumer | D20: Bongani Nhlanzi | E20: OPP143239 | F20: 14550816 | H20: 1746097.9 | I20: 0.12 | J20: Upside | K20: 2026/06/01 | M20: No | N20: Quote Created | O20: Low
B21: ITSS Cisco Products | C21: Pep A Division Of Pepkor Trading (PTd | D21: Freddy Abrahams | E21: OPP135155 | F21: 11735414 | H21: 821479.01 | I21: 0.07 | J21: Upside | K21: 2026/11/01 | M21: No | N21: Quote Created | O21: Low | Q21: Paul van Rooyen; Roan van Nieuwenhuizen
B22: ITSS Cisco Products | C22: Electoral Commission of SouthAfrica Iec | D22: John Croone | E22: OPP139758/03 | F22: 10809716 | H22: 1621457.4 | I22: 0.15 | J22: Commit | K22: 2026/09/01 | M22: No | N22: Shortlist/Verbal Commitment/Awaiting Client PO | O22: High

Sheet BCX Internal
A1: LOB INPUT | B1: Customer Name | C1: Sales Vertical | D1: OPP Number | E1: Gross Revenue | F1: Expected Net Revenue | G1: GP Value | H1: GP % | I1: Deal Status | J1: Billing Month | L1: Billing Status | M1: Source | N1: Deal Probability | O1: Extra Notes | P1: Presales Name | Q1: LOB / BDM Name | R1: Deal Type | S1: Update | T1: FY Qrt list | U1: Medium high chase
A2: ITSS Cisco LoB | B2: BCX DC & Core | C2: Mining Indust&Health | D2: BCX Internal | E2: 28276225 | F2: 0 | G2: 0 | H2: 0 | J2: 46296 | L2: No | M2: Upside Deal | N2: Low | O2: Checked | P2: Johan Taljaard | Q2: Wimpie Pieterse | R2: Product | S2: BCX spine refresh
A3: ITSS Cisco LoB | B3: BCX Concom | C3: Mining Indust&Health | D3: BCX Internal | E3: 6957253 | F3: 0 | G3: 0 | H3: 0 | J3: 46296 | L3: No | M3: Upside Deal | N3: Low | O3: Checked | P3: Johan Taljaard | Q3: Wimpie Pieterse | R3: Software / Licence | S3: Secure Connect Licensing
A4: ITSS Cisco LoB | B4: BCX DC & Core | C4: Mining Indust&Health | D4: BCX Internal | E4: 3710083 | F4: 0 | G4: 0 | H4: 0 | J4: 46296 | L4: No | M4: Upside Deal | N4: Medium | O4: Checked | P4: Johan Taljaard | Q4: Wimpie Pieterse | R4: OEM Service | S4: Cisco prof service APIC and MSO
A5: ITSS Cisco LoB | B5: BCX Concom | C5: Mining Indust&Health | D5: BCX Internal | E5: 5225742.3 | F5: 0 | G5: 0 | H5: 0 | J5: 46174 | L5: No | M5: Backlog Deal | N5: High | O5: Checked | P5: Johan Taljaard | Q5: Wimpie Pieterse | R5: Software / Licence | S5: Meraki licenses
A6: ITSS Cisco LoB | B6: BCX DC & Core | C6: Mining Indust&Health | D6: BCX Internal | E6: 2359798 | F6: 0 | G6: 0 | H6: 0 | J6: 46296 | L6: No | M6: Upside Deal | N6: Medium | O6: Checked | P6: Johan Taljaard | Q6: Wimpie Pieterse | R6: Product | S6: APIC refresh
A7: ITSS Cisco LoB | B7: BCX Wifi | C7: Mining Indust&Health | D7: BCX Internal | E7: 1771002 | F7: 0 | G7: 0 | H7: 0 | J7: 46174 | L7: No | M7: Backlog Deal | N7: High | O7: Checked | P7: Johan Taljaard | Q7: Wimpie Pieterse | R7: Product | S7: BCX Wifi AP's - Approved by SRC
A8: ITSS Cisco LoB | B8: Telkom SA SOC Limited | C8: Mining Indust&Health | D8: BCX Internal | E8: 49992166 | F8: 0 | G8: 0 | H8: 1 | J8: 46204 | K8: FY 27 Q1 | L8: No | M8: Backlog Deal | N8: High | O8: checked | P8: johan Taljaard | Q8: Wimpie Pieterse | R8: OEM Service | S8: BCX SFC Year 3/3

Sheet Monitor status

Sheet Noted losses
A1: LOB INPUT
D2: Totals | E2: =SUM(E4:E161992) -> 1334045 | F2: =SUM(F4:F161992) -> 1334045 | G2: =SUM(G4:G161992) -> 160085.4
A3: LOB INPUT | B3: Customer Name | C3: Sales Vertical | D3: OPP Number | E3: Gross Revenue | F3: Expected Net Revenue | G3: GP Value | H3: GP % | I3: Deal Status | J3: Billing Month | K3: FY Qrt list | L3: Billing Status | M3: Source | N3: Deal Probability | O3: Extra Notes | P3: Presales Name | Q3: LOB / BDM Name | R3: Deal Type | S3: Update | T3: Medium high chase
A4: ITSS Cisco LoB | B4: Momentum Metropolitan Life Ltd Metropolitan | C4: FSI & Retail | D4: OPP146912 | E4: 1334045 | F4: 1334045 | G4: 160085.4 | H4: 0.12 | I4: Upside | J4: 46266 | K4: FY 27 Q2 | L4: No | M4: Upside Deal | N4: High | P4: Wandile Dlamini | Q4: Wimpie Pieterse | R4: Product | S4: CUSTOMER DECIDED TO GO WITH ANOTHER SOLUTION BECAUSE OF LEAD TIMES

Sheet DealDefinitions
B2: Deal Status | C2: Source | D2: Deal Probability | E2: Definition | F2: Risk Factors
B3: Commit | C3: Backlog Deal | D3: No Risk | E3: Historical month consolidated | F3: None - Money in the bank
B4: Commit | C4: Backlog Deal | D4: High | E4: PO placed on OEM/ Supplier | F4: Timing to invoice/ Recognise
B5: Commit | C5: Commit | D5: High | E5: Award letter/ Written commitement - no PO | F5: Timing to PO
B6: Upside | C6: Upside | D6: High | E6: Verbal commitment/ Very high confidence | F6: Competition/ Timing
B7: Upside | C7: Upside | D7: Medium | E7: No customer commitment/incumbancy/Medium to High confidence | F7: Competition/ Cancellation
B8: Upside | C8: Upside | D8: Low | E8: Tender/ Medium to Low confidence | F8: Competition/ Cancellation

Sheet Cisco view
A1: LOB INPUT
D2: Totals | E2: =SUM(E4:E222) -> #REF!
A3: ='Current Cadence'!A3 -> LOB INPUT | B3: ='Current Cadence'!B3 -> Customer Name | C3: ='Current Cadence'!C3 -> Sales Vertical | D3: ='Current Cadence'!D3 -> OPP Number | E3: ='Current Cadence'!E3 -> Gross Revenue | F3: ='Current Cadence'!I3 -> Deal Status | G3: ='Current Cadence'!J3 -> Billing Month | H3: ='Current Cadence'!K3 -> FY Qrt list | I3: ='Current Cadence'!L3 -> Billing Status | J3: ='Current Cadence'!M3 -> Source | K3: ='Current Cadence'!N3 -> Deal Probability | L3: ='Current Cadence'!O3 -> Extra Notes | M3: ='Current Cadence'!P3 -> Presales Name | ... U3: ='Current Cadence'!X3 -> 0
A4: ='Current Cadence'!A4 -> ITSS Cisco LoB | B4: ='Current Cadence'!B4 -> South African Revenue Services | C4: ='Current Cadence'!C4 -> Public | D4: ='Current Cadence'!D4 -> OPP145398 | E4: ='Current Cadence'!E4 -> 2.4910934e+08 | F4: ='Current Cadence'!I4 -> Upside | G4: ='Current Cadence'!J4 -> 46447 | H4: ='Current Cadence'!K4 -> FY 27 Q4 | I4: ='Current Cadence'!L4 -> No | J4: ='Current Cadence'!M4 -> Upside Deal | K4: ='Current Cadence'!N4 -> Low | L4: ='Current Cadence'!O4 -> 0 | M4: ='Current Cadence'!P4 -> David Ramorola | ... U4: ='Current Cadence'!X4 -> 0
A5: ='Current Cadence'!A5 -> ITSS Cisco LoB | B5: ='Current Cadence'!B5 -> South African Social Agency (SASSA) | C5: ='Current Cadence'!C5 -> Public | D5: ='Current Cadence'!D5 -> OPP146677 | E5: ='Current Cadence'!E5 -> 1.235666e+08 | F5: ='Current Cadence'!I5 -> Upside | G5: ='Current Cadence'!J5 -> 46447 | H5: ='Current Cadence'!K5 -> FY 27 Q4 | I5: ='Current Cadence'!L5 -> No | J5: ='Current Cadence'!M5 -> Upside Deal | K5: ='Current Cadence'!N5 -> Low | L5: ='Current Cadence'!O5 -> 0 | M5: ='Current Cadence'!P5 -> David Ramorola | ... O5: ='Current Cadence'!R5 -> Product | P5: Howard to checkup with Viloshnee on next steps | Q5: ='Current Cadence'!T5 -> 0 | R5: ='Current Cadence'!U5 -> 0 | S5: ='Current Cadence'!V5 -> 0 | T5: ='Current Cadence'!W5 -> 0 | U5: ='Current Cadence'!X5 -> 0
A6: ='Current Cadence'!A6 -> ITSS Cisco LoB | B6: ='Current Cadence'!B6 -> The Spar Group Ltd | C6: ='Current Cadence'!C6 -> FSI & Retail | D6: ='Current Cadence'!D6 -> OPP136919 | E6: ='Current Cadence'!E6 -> 38123456 | F6: ='Current Cadence'!I6 -> Upside | G6: ='Current Cadence'!J6 -> 46174 | H6: ='Current Cadence'!K6 -> FY 27 Q1 | I6: ='Current Cadence'!L6 -> No | J6: ='Current Cadence'!M6 -> Upside Deal | K6: ='Current Cadence'!N6 -> High | L6: ='Current Cadence'!O6 -> checked | M6: ='Current Cadence'!P6 -> Roan van Nieuwenhuizen | ... U6: ='Current Cadence'!X6 -> 0
A7: ='Current Cadence'!A7 -> ITSS Cisco LoB | B7: ='Current Cadence'!B7 -> Telkom Consumer | C7: ='Current Cadence'!C7 -> Mining Indust&Health | D7: ='Current Cadence'!D7 -> OPP133098 | E7: ='Current Cadence'!E7 -> 33825197 | F7: ='Current Cadence'!I7 -> Commit | G7: ='Current Cadence'!J7 -> 46174 | H7: ='Current Cadence'!K7 -> FY 27 Q1 | I7: ='Current Cadence'!L7 -> No | J7: ='Current Cadence'!M7 -> Backlog Deal | K7: ='Current Cadence'!N7 -> High | L7: ='Current Cadence'!O7 -> checked | M7: ='Current Cadence'!P7 -> johan Taljaard | ... U7: ='Current Cadence'!X7 -> 0
A8: ='Current Cadence'!A8 -> ITSS Cisco LoB | B8: ='Current Cadence'!B8 -> Discovery Central Services (Pty) Ltd | C8: ='Current Cadence'!C8 -> FSI & Retail | D8: ='Current Cadence'!D8 -> OPP147096 | E8: ='Current Cadence'!E8 -> 30614619 | F8: ='Current Cadence'!I8 -> Upside | G8: ='Current Cadence'!J8 -> 46235 | H8: ='Current Cadence'!K8 -> FY 27 Q2 | I8: ='Current Cadence'!L8 -> No | J8: ='Current Cadence'!M8 -> Upside Deal | K8: ='Current Cadence'!N8 -> Low | L8: ='Current Cadence'!O8 -> checked | M8: ='Current Cadence'!P8 -> Paul van Rooyen | ... U8: ='Current Cadence'!X8 -> 0
A9: ='Current Cadence'!A9 -> ITSS Cisco LoB | B9: ='Current Cadence'!B9 -> Telkom ISP | C9: ='Current Cadence'!C9 -> Mining Indust&Health | D9: ='Current Cadence'!D9 -> OPP147364 | E9: ='Current Cadence'!E9 -> 28723558 | F9: ='Current Cadence'!I9 -> Upside | G9: ='Current Cadence'!J9 -> 46327 | H9: ='Current Cadence'!K9 -> FY 27 Q3 | I9: ='Current Cadence'!L9 -> No | J9: ='Current Cadence'!M9 -> Upside Deal | K9: ='Current Cadence'!N9 -> Medium | L9: ='Current Cadence'!O9 -> checked | M9: ='Current Cadence'!P9 -> Johan Taljaard | ... U9: ='Current Cadence'!X9 -> 0
A10: ='Current Cadence'!A10 -> ITSS Cisco LoB | B10: ='Current Cadence'!B10 -> Openserve | C10: ='Current Cadence'!C10 -> Mining Indust&Health | D10: ='Current Cadence'!D10 -> OPP145768 | E10: ='Current Cadence'!E10 -> 21938053 | F10: ='Current Cadence'!I10 -> Upside | G10: ='Current Cadence'!J10 -> 46327 | H10: ='Current Cadence'!K10 -> FY 27 Q3 | I10: ='Current Cadence'!L10 -> No | J10: ='Current Cadence'!M10 -> Upside Deal | K10: ='Current Cadence'!N10 -> Medium | L10: ='Current Cadence'!O10 -> checked | M10: ='Current Cadence'!P10 -> Johan Taljaard | ... U10: ='Current Cadence'!X10 -> 0
A11: ='Current Cadence'!A11 -> ITSS Cisco LoB | B11: ='Current Cadence'!B11 -> Telkom Consumer | C11: ='Current Cadence'!C11 -> Mining Indust&Health | D11: ='Current Cadence'!D11 -> OPP147259 | E11: ='Current Cadence'!E11 -> 21938052 | F11: ='Current Cadence'!I11 -> Upside | G11: ='Current Cadence'!J11 -> 46327 | H11: ='Current Cadence'!K11 -> FY 27 Q3 | I11: ='Current Cadence'!L11 -> No | J11: ='Current Cadence'!M11 -> Upside Deal | K11: ='Current Cadence'!N11 -> Low | L11: ='Current Cadence'!O11 -> checked | M11: ='Current Cadence'!P11 -> Johan Taljaard | ... U11: ='Current Cadence'!X11 -> 0
A12: ='Current Cadence'!A12 -> ITSS Cisco LoB | B12: ='Current Cadence'!B12 -> The Standard Bank of South Africa | C12: ='Current Cadence'!C12 -> FSI & Retail | D12: ='Current Cadence'!D12 -> OPP13777 | E12: ='Current Cadence'!E12 -> 17211644 | F12: ='Current Cadence'!I12 -> Commit | G12: ='Current Cadence'!J12 -> 46478 | H12: ='Current Cadence'!K12 | I12: ='Current Cadence'!L12 -> No | J12: ='Current Cadence'!M12 -> Backlog Deal | K12: ='Current Cadence'!N12 -> High | L12: ='Current Cadence'!O12 -> Checked | M12: ='Current Cadence'!P12 -> Paul van Rooyen | ... U12: ='Current Cadence'!X12 -> 0
A13: ='Current Cadence'!A13 -> ITSS Cisco LoB | B13: ='Current Cadence'!B13 -> Telkom Consumer | C13: ='Current Cadence'!C13 -> Mining Indust&Health | D13: ='Current Cadence'!D13 -> OPP135119/01 | E13: ='Current Cadence'!E13 -> 15799289 | F13: ='Current Cadence'!I13 -> Upside | G13: ='Current Cadence'!J13 -> 46327 | H13: ='Current Cadence'!K13 -> FY 27 Q3 | I13: ='Current Cadence'!L13 -> No | J13: ='Current Cadence'!M13 -> Upside Deal | K13: ='Current Cadence'!N13 -> Medium | L13: ='Current Cadence'!O13 -> checked | M13: ='Current Cadence'!P13 -> Johan Taljaard | ... U13: ='Current Cadence'!X13 -> 0
A14: ='Current Cadence'!A14 -> ITSS Cisco LoB | B14: ='Current Cadence'!B14 -> Openserve | C14: ='Current Cadence'!C14 -> Mining Indust&Health | D14: ='Current Cadence'!D14 -> OPP141512/01 | E14: ='Current Cadence'!E14 -> 14895000 | F14: ='Current Cadence'!I14 -> Upside | G14: ='Current Cadence'!J14 -> 46327 | H14: ='Current Cadence'!K14 -> FY 27 Q3 | I14: ='Current Cadence'!L14 -> No | J14: ='Current Cadence'!M14 -> Upside Deal | K14: ='Current Cadence'!N14 -> Medium | L14: ='Current Cadence'!O14 -> checked | M14: ='Current Cadence'!P14 -> Johan Taljaard | ... U14: ='Current Cadence'!X14 -> 0
A15: ='Current Cadence'!A15 -> ITSS Cisco LoB | B15: ='Current Cadence'!B15 -> SANBS | C15: ='Current Cadence'!C15 -> Public | D15: ='Current Cadence'!D15 -> OPP146783 | E15: ='Current Cadence'!E15 -> 14433451 | F15: ='Current Cadence'!I15 -> Upside | G15: ='Current Cadence'!J15 -> 46296 | H15: ='Current Cadence'!K15 -> FY 27 Q3 | I15: ='Current Cadence'!L15 -> No | J15: ='Current Cadence'!M15 -> Upside Deal | K15: ='Current Cadence'!N15 -> Low | L15: ='Current Cadence'!O15 -> Checked | M15: ='Current Cadence'!P15 -> Wandile Dlamini | ... U15: ='Current Cadence'!X15 -> 0
A16: ='Current Cadence'!A16 -> ITSS Cisco LoB | B16: ='Current Cadence'!B16 -> Nedbank Limited | C16: ='Current Cadence'!C16 -> FSI & Retail | D16: ='Current Cadence'!D16 -> OPP147252 | E16: ='Current Cadence'!E16 -> 14378595 | F16: ='Current Cadence'!I16 -> Upside | G16: ='Current Cadence'!J16 -> 46266 | H16: ='Current Cadence'!K16 -> FY 27 Q2 | I16: ='Current Cadence'!L16 -> No | J16: ='Current Cadence'!M16 -> Upside Deal | K16: ='Current Cadence'!N16 -> Low | L16: ='Current Cadence'!O16 -> 0 | M16: ='Current Cadence'!P16 -> Sean Royds | ... U16: ='Current Cadence'!X16 -> 0
A17: ='Current Cadence'!A17 -> ITSS Cisco LoB | B17: ='Current Cadence'!B17 -> Openserve (Pty) Ltd | C17: ='Current Cadence'!C17 -> Mining Indust&Health | D17: ='Current Cadence'!D17 -> OPP145588 | E17: ='Current Cadence'!E17 -> 13312345 | F17: ='Current Cadence'!I17 -> Upside | G17: ='Current Cadence'!J17 -> 46174 | H17: ='Current Cadence'!K17 -> FY 27 Q1 | I17: ='Current Cadence'!L17 -> No | J17: ='Current Cadence'!M17 -> Upside Deal | K17: ='Current Cadence'!N17 -> High | L17: ='Current Cadence'!O17 -> checked | M17: ='Current Cadence'!P17 -> Johan Taljaard | ... U17: ='Current Cadence'!X17 -> 0
... A19: ='Current Cadence'!A19 -> ITSS Cisco LoB | B19: ='Current Cadence'!B19 -> Telkom | C19: ='Current Cadence'!C19 -> Mining Indust&Health | D19: ='Current Cadence'!D19 -> OPP135119 | E19: ='Current Cadence'!E19 -> 13162789 | F19: ='Current Cadence'!I19 -> Upside | G19: ='Current Cadence'!J19 -> 46327 | H19: ='Current Cadence'!K19 -> FY 27 Q3 | I19: ='Current Cadence'!L19 -> No | J19: ='Current Cadence'!M19 -> Upside Deal | K19: ='Current Cadence'!N19 -> Medium | L19: ='Current Cadence'!O19 -> checked | M19: ='Current Cadence'!P19 -> Johan Taljaard | ... U19: ='Current Cadence'!X19 -> 0
A20: ='Current Cadence'!#REF! -> #REF! | B20: ='Current Cadence'!#REF! -> #REF! | C20: ='Current Cadence'!#REF! -> #REF! | D20: ='Current Cadence'!#REF! -> #REF! | E20: ='Current Cadence'!#REF! -> #REF! | F20: ='Current Cadence'!#REF! -> #REF! | G20: ='Current Cadence'!#REF! -> #REF! | H20: ='Current Cadence'!#REF! -> #REF! | ... U20: ='Current Cadence'!#REF! -> #REF!
A21: ='Current Cadence'!A20 -> ITSS Cisco LoB | B21: ='Current Cadence'!B20 -> Telkom Consumer | C21: ='Current Cadence'!C20 -> Mining Indust&Health | D21: ='Current Cadence'!D20 -> OPP142649/02 | E21: ='Current Cadence'!E20 -> 13140597 | F21: ='Current Cadence'!I20 -> Upside | G21: ='Current Cadence'!J20 -> 46327 | H21: ='Current Cadence'!K20 -> FY 27 Q3 | I21: ='Current Cadence'!L20 -> No | J21: ='Current Cadence'!M20 -> Upside Deal | K21: ='Current Cadence'!N20 -> Medium | L21: ='Current Cadence'!O20 -> checked | M21: ='Current Cadence'!P20 -> Johan Taljaard | ... U21: ='Current Cadence'!X20 -> 0
A22: ='Current Cadence'!A21 -> ITSS Cisco LoB | B22: ='Current Cadence'!B21 -> Openserve | C22: ='Current Cadence'!C21 -> Mining Indust&Health | D22: ='Current Cadence'!D21 -> OPP148548 | E22: ='Current Cadence'!E21 -> 12449770 | F22: ='Current Cadence'!I21 -> Upside | G22: ='Current Cadence'!J21 -> 46327 | H22: ='Current Cadence'!K21 -> FY 27 Q3 | I22: ='Current Cadence'!L21 -> No | J22: ='Current Cadence'!M21 -> Upside Deal | K22: ='Current Cadence'!N21 -> Medium | L22: ='Current Cadence'!O21 -> OPP148548 Openserve SPINE Switches - Tygerburg & Core | M22: ='Current Cadence'!P21 -> Johan Taljaard | ... U22: ='Current Cadence'!X21 -> 0
A23: ='Current Cadence'!A22 -> ITSS Cisco LoB | B23: ='Current Cadence'!B22 -> Air Traffic and Navigation ServicesCompany Limited | C23: ='Current Cadence'!C22 -> Public | D23: ='Current Cadence'!D22 -> OPP123907 | E23: ='Current Cadence'!E22 -> 12000000 | F23: ='Current Cadence'!I22 -> Upside | G23: ='Current Cadence'!J22 -> 46447 | H23: ='Current Cadence'!K22 -> FY 27 Q4 | I23: ='Current Cadence'!L22 -> No | J23: ='Current Cadence'!M22 -> Upside Deal | K23: ='Current Cadence'!N22 -> Low | L23: ='Current Cadence'!O22 -> Checked | M23: ='Current Cadence'!P22 -> Wandile Dlamini | ... U23: ='Current Cadence'!X22 -> 0
A24: ='Current Cadence'!#REF! -> #REF! | B24: ='Current Cadence'!#REF! -> #REF! | C24: ='Current Cadence'!#REF! -> #REF! | D24: ='Current Cadence'!#REF! -> #REF! | E24: ='Current Cadence'!#REF! -> #REF! | F24: ='Current Cadence'!#REF! -> #REF! | G24: ='Current Cadence'!#REF! -> #REF! | H24: ='Current Cadence'!#REF! -> #REF! | ... U24: ='Current Cadence'!#REF! -> #REF!
A25: ='Current Cadence'!A23 -> ITSS Cisco LoB | B25: ='Current Cadence'!B23 -> Telkom SA SOC Limited | C25: ='Current Cadence'!C23 -> Mining Indust&Health | D25: ='Current Cadence'!D23 -> OPP122332/04 | E25: ='Current Cadence'!E23 -> 11391262 | F25: ='Current Cadence'!I23 -> Commit | G25: ='Current Cadence'!J23 -> 46204 | H25: ='Current Cadence'!K23 -> FY 27 Q2 | I25: ='Current Cadence'!L23 -> No | J25: ='Current Cadence'!M23 -> Backlog Deal | K25: ='Current Cadence'!N23 -> High | L25: ='Current Cadence'!O23 -> checked | M25: ='Current Cadence'!P23 -> johan Taljaard | ... U25: ='Current Cadence'!X23 -> 0
A26: ='Current Cadence'!#REF! -> #REF! | B26: ='Current Cadence'!#REF! -> #REF! | C26: ='Current Cadence'!#REF! -> #REF! | D26: ='Current Cadence'!#REF! -> #REF! | E26: ='Current Cadence'!#REF! -> #REF! | F26: ='Current Cadence'!#REF! -> #REF! | G26: ='Current Cadence'!#REF! -> #REF! | H26: ='Current Cadence'!#REF! -> #REF! | ... U26: ='Current Cadence'!#REF! -> #REF!
A27: ='Current Cadence'!A24 -> ITSS Cisco LoB | B27: ='Current Cadence'!B24 -> Western Cape Government Health | C27: ='Current Cadence'!C24 -> Public | D27: ='Current Cadence'!D24 -> OPP140607 | E27: ='Current Cadence'!E24 -> 10854175 | F27: ='Current Cadence'!I24 -> Upside | G27: ='Current Cadence'!J24 -> 46296 | H27: ='Current Cadence'!K24 -> FY 27 Q3 | I27: ='Current Cadence'!L24 -> No | J27: ='Current Cadence'!M24 -> Upside Deal | K27: ='Current Cadence'!N24 -> Low | L27: ='Current Cadence'!O24 -> Checked | M27: ='Current Cadence'!P24 -> Wandile Dlamini | ... U27: ='Current Cadence'!X24 -> 0
A28: ='Current Cadence'!A25 -> ITSS Cisco LoB | B28: ='Current Cadence'!B25 -> Telkom Consumer | C28: ='Current Cadence'!C25 -> Mining Indust&Health | D28: ='Current Cadence'!D25 -> OPP142649/01 | E28: ='Current Cadence'!E25 -> 10827243 | F28: ='Current Cadence'!I25 -> Upside | G28: ='Current Cadence'!J25 -> 46327 | H28: ='Current Cadence'!K25 -> FY 27 Q3 | I28: ='Current Cadence'!L25 -> No | J28: ='Current Cadence'!M25 -> Upside Deal | K28: ='Current Cadence'!N25 -> Medium | L28: ='Current Cadence'!O25 -> checked | M28: ='Current Cadence'!P25 -> Johan Taljaard | ... U28: ='Current Cadence'!X25 -> 0
A29: ='Current Cadence'!A26 -> ITSS Cisco LoB | B29: ='Current Cadence'!B26 -> Tiger Brands | C29: ='Current Cadence'!C26 -> FSI & Retail | D29: ='Current Cadence'!D26 -> OPP138466 | E29: ='Current Cadence'!E26 -> 10753040 | F29: ='Current Cadence'!I26 -> Upside | G29: ='Current Cadence'!J26 -> 46204 | H29: ='Current Cadence'!K26 -> FY 27 Q2 | I29: ='Current Cadence'!L26 -> No | J29: ='Current Cadence'!M26 -> Upside Deal | K29: ='Current Cadence'!N26 -> Low | L29: ='Current Cadence'!O26 -> Checked | M29: ='Current Cadence'!P26 -> Nowell Duze | ... U29: ='Current Cadence'!X26 -> 0
A30: ='Current Cadence'!A27 -> ITSS Cisco LoB | B30: ='Current Cadence'!B27 -> Pep A Division Of Pepkor Trading (PTd | C30: ='Current Cadence'!C27 -> Corporate | D30: ='Current Cadence'!D27 -> OPP146179 | E30: ='Current Cadence'!E27 -> 8123456 | F30: ='Current Cadence'!I27 -> Upside | G30: ='Current Cadence'!J27 -> 46327 | H30: ='Current Cadence'!K27 -> FY 27 Q3 | I30: ='Current Cadence'!L27 -> No | J30: ='Current Cadence'!M27 -> Upside Deal | K30: ='Current Cadence'!N27 -> High | L30: ='Current Cadence'!O27 -> checked | M30: ='Current Cadence'!P27 -> Roan van Nieuwenhuizen | ... U30: ='Current Cadence'!X27 -> 0
A31: ='Current Cadence'!#REF! -> #REF! | B31: ='Current Cadence'!#REF! -> #REF! | C31: ='Current Cadence'!#REF! -> #REF! | D31: ='Current Cadence'!#REF! -> #REF! | E31: ='Current Cadence'!#REF! -> #REF! | F31: ='Current Cadence'!#REF! -> #REF! | G31: ='Current Cadence'!#REF! -> #REF! | H31: ='Current Cadence'!#REF! -> #REF! | ... U31: ='Current Cadence'!#REF! -> #REF!
A32: ='Current Cadence'!A28 -> ITSS Cisco LoB | B32: ='Current Cadence'!B28 -> Durban ICC | C32: ='Current Cadence'!C28 -> Public | D32: ='Current Cadence'!D28 -> OPP145736 | E32: ='Current Cadence'!E28 -> 7845333 | F32: ='Current Cadence'!I28 -> Upside | G32: ='Current Cadence'!J28 -> 46266 | H32: ='Current Cadence'!K28 -> FY 27 Q2 | I32: ='Current Cadence'!L28 -> No | J32: ='Current Cadence'!M28 -> Upside Deal | K32: ='Current Cadence'!N28 -> Medium | L32: ='Current Cadence'!O28 -> Checked | M32: ='Current Cadence'!P28 -> Wandile Dlamini | ... U32: ='Current Cadence'!X28 -> 0
A33: ='Current Cadence'!A29 -> ITSS Cisco LoB | B33: ='Current Cadence'!B29 -> Volkswagen Group Africa (Pty) Ltd | C33: ='Current Cadence'!C29 -> Corporate | D33: ='Current Cadence'!D29 -> OPP148038 | E33: ='Current Cadence'!E29 -> 7461453 | F33: ='Current Cadence'!I29 -> Upside | G33: ='Current Cadence'!J29 -> 46235 | H33: ='Current Cadence'!K29 -> FY 27 Q2 | I33: ='Current Cadence'!L29 -> No | J33: ='Current Cadence'!M29 -> Upside Deal | K33: ='Current Cadence'!N29 -> Low | L33: ='Current Cadence'!O29 -> 0 | M33: ='Current Cadence'!P29 -> Roan van Nieuwenhuizen | ... U33: ='Current Cadence'!X29 -> 0
A34: ='Current Cadence'!A30 -> ITSS Cisco LoB | B34: ='Current Cadence'!B30 -> Electoral Commission of SouthAfrica Iec | C34: ='Current Cadence'!C30 -> Public | D34: ='Current Cadence'!D30 -> OPP147418 | E34: ='Current Cadence'!E30 -> 7405205 | F34: ='Current Cadence'!I30 -> Upside | G34: ='Current Cadence'!J30 -> 46266 | H34: ='Current Cadence'!K30 -> FY 27 Q2 | I34: ='Current Cadence'!L30 -> No | J34: ='Current Cadence'!M30 -> Upside Deal | K34: ='Current Cadence'!N30 -> Low | L34: ='Current Cadence'!O30 -> 0 | M34: ='Current Cadence'!P30 -> Roan van Nieuwenhuizen | ... U34: ='Current Cadence'!X30 -> 0
A35: ='Current Cadence'!A31 -> ITSS Cisco LoB | B35: ='Current Cadence'!B31 -> Electoral Commission of SouthAfrica Iec | C35: ='Current Cadence'!C31 -> Public | D35: ='Current Cadence'!D31 -> OPP139758 | E35: ='Current Cadence'!E31 -> 7056976.2 | F35: ='Current Cadence'!I31 -> Commit | G35: ='Current Cadence'!J31 -> 46235 | H35: ='Current Cadence'!K31 -> FY 27 Q2 | I35: ='Current Cadence'!L31 -> No | J35: ='Current Cadence'!M31 -> Backlog Deal | K35: ='Current Cadence'!N31 -> High | L35: ='Current Cadence'!O31 -> Checked | M35: ='Current Cadence'!P31 -> David Ramorola | ... U35: ='Current Cadence'!X31 -> 0
A36: ='Current Cadence'!A32 -> ITSS Cisco LoB | B36: ='Current Cadence'!B32 -> Pep A Division Of Pepkor Trading (PTd | C36: ='Current Cadence'!C32 -> Corporate | D36: ='Current Cadence'!D32 -> OPP141566 | E36: ='Current Cadence'!E32 -> 6991803.2 | F36: ='Current Cadence'!I32 -> Upside | G36: ='Current Cadence'!J32 -> 46419 | H36: ='Current Cadence'!K32 -> FY 27 Q4 | I36: ='Current Cadence'!L32 -> No | J36: ='Current Cadence'!M32 -> Upside Deal | K36: ='Current Cadence'!N32 -> Medium | L36: ='Current Cadence'!O32 -> checked | M36: ='Current Cadence'!P32 -> Paul van Rooyen | ... U36: ='Current Cadence'!X32 -> 0
A37: ='Current Cadence'!A33 -> ITSS Cisco LoB | B37: ='Current Cadence'!B33 -> Nedbank Limited | C37: ='Current Cadence'!C33 -> FSI & Retail | D37: ='Current Cadence'!D33 -> OPP147043 | E37: ='Current Cadence'!E33 -> 5790700.2 | F37: ='Current Cadence'!I33 -> Commit | G37: ='Current Cadence'!J33 -> 46204 | H37: ='Current Cadence'!K33 -> FY 27 Q2 | I37: ='Current Cadence'!L33 -> No | J37: ='Current Cadence'!M33 -> Backlog Deal | K37: ='Current Cadence'!N33 -> High | L37: ='Current Cadence'!O33 -> 0 | M37: ='Current Cadence'!P33 -> Sean Royds | ... U37: ='Current Cadence'!X33 -> 0
A38: ='Current Cadence'!A34 -> ITSS Cisco LoB | B38: ='Current Cadence'!B34 -> Volkswagen Group Africa (Pty) Ltd | C38: ='Current Cadence'!C34 -> Corporate | D38: ='Current Cadence'!D34 -> OPP146486 | E38: ='Current Cadence'!E34 -> 5751314 | F38: ='Current Cadence'!I34 -> Upside | G38: ='Current Cadence'!J34 -> 46235 | H38: ='Current Cadence'!K34 -> FY 27 Q2 | I38: ='Current Cadence'!L34 -> No | J38: ='Current Cadence'!M34 -> Upside Deal | K38: ='Current Cadence'!N34 -> Low | L38: ='Current Cadence'!O34 -> 0 | M38: ='Current Cadence'!P34 -> Roan van Nieuwenhuizen | ... U38: ='Current Cadence'!X34 -> 0
A39: ='Current Cadence'!A35 -> ITSS Cisco LoB | B39: ='Current Cadence'!B35 -> Capitec Bank Limited | C39: ='Current Cadence'!C35 -> FSI & Retail | D39: ='Current Cadence'!D35 -> OPP089485 | E39: ='Current Cadence'!E35 -> 5699203 | F39: ='Current Cadence'!I35 -> Commit | G39: ='Current Cadence'!J35 -> 46327 | H39: ='Current Cadence'!K35 -> FY 27 Q3 | I39: ='Current Cadence'!L35 -> No | J39: ='Current Cadence'!M35 -> Backlog Deal | K39: ='Current Cadence'!N35 -> High | L39: ='Current Cadence'!O35 -> checked | M39: ='Current Cadence'!P35 -> Paul van Rooyen | ... U39: ='Current Cadence'!X35 -> 0
A40: ='Current Cadence'!A36 -> ITSS Cisco LoB | B40: ='Current Cadence'!B36 -> Tiger Brands | C40: ='Current Cadence'!C36 -> FSI & Retail | D40: ='Current Cadence'!D36 -> OPP146660 | E40: ='Current Cadence'!E36 -> 5301769.3 | F40: ='Current Cadence'!I36 -> Upside | G40: ='Current Cadence'!J36 -> 46204 | H40: ='Current Cadence'!K36 -> FY 27 Q2 | I40: ='Current Cadence'!L36 -> No | J40: ='Current Cadence'!M36 -> Upside Deal | K40: ='Current Cadence'!N36 -> Low | L40: ='Current Cadence'!O36 -> Checked | M40: ='Current Cadence'!P36 -> Nowell Duze | ... U40: ='Current Cadence'!X36 -> 0
A41: ='Current Cadence'!A37 -> ITSS Cisco LoB | B41: ='Current Cadence'!B37 -> Momentum Metropolitan Life Ltd Metropolitan | C41: ='Current Cadence'!C37 -> FSI & Retail | D41: ='Current Cadence'!D37 -> OPP142558 | E41: ='Current Cadence'!E37 -> 5238762.6 | F41: ='Current Cadence'!I37 -> Commit | G41: ='Current Cadence'!J37 -> 46143 | H41: ='Current Cadence'!K37 -> FY 27 Q1 | I41: ='Current Cadence'!L37 -> Yes | J41: ='Current Cadence'!M37 -> Backlog Deal | K41: ='Current Cadence'!N37 -> High | L41: ='Current Cadence'!O37 -> Checked | M41: ='Current Cadence'!P37 -> Wandile Dlamini | ... U41: ='Current Cadence'!X37 -> 0
...

Sheet DupeCheck
A1: {=_xlfn.UNIQUE('Current Cadence'!D:D)} -> 0 | B1: =COUNTIF('Current Cadence'!D:D,DupeCheck!A1) -> 0
A2: Totals | B2: =COUNTIF('Current Cadence'!D:D,DupeCheck!A2) -> 1
A3: OPP Number | B3: =COUNTIF('Current Cadence'!D:D,DupeCheck!A3) -> 1
A4: OPP145398 | B4: =COUNTIF('Current Cadence'!D:D,DupeCheck!A4) -> 1
A5: OPP146677 | B5: =COUNTIF('Current Cadence'!D:D,DupeCheck!A5) -> 1
A6: OPP136919 | B6: =COUNTIF('Current Cadence'!D:D,DupeCheck!A6) -> 1
A7: OPP133098 | B7: =COUNTIF('Current Cadence'!D:D,DupeCheck!A7) -> 1
A8: OPP147096 | B8: =COUNTIF('Current Cadence'!D:D,DupeCheck!A8) -> 1
A9: OPP147364 | B9: =COUNTIF('Current Cadence'!D:D,DupeCheck!A9) -> 1
A10: OPP145768 | B10: =COUNTIF('Current Cadence'!D:D,DupeCheck!A10) -> 1
A11: OPP147259 | B11: =COUNTIF('Current Cadence'!D:D,DupeCheck!A11) -> 1
A12: OPP13777 | B12: =COUNTIF('Current Cadence'!D:D,DupeCheck!A12) -> 1
A13: OPP135119/01 | B13: =COUNTIF('Current Cadence'!D:D,DupeCheck!A13) -> 1
... A180: OPP139075 | B180: =COUNTIF('Current Cadence'!D:D,DupeCheck!A180) -> 1
B181: =COUNTIF('Current Cadence'!D:D,DupeCheck!A181) -> 0
B182: =COUNTIF('Current Cadence'!D:D,DupeCheck!A182) -> 0
B183: =COUNTIF('Current Cadence'!D:D,DupeCheck!A183) -> 0
B184: =COUNTIF('Current Cadence'!D:D,DupeCheck!A184) -> 0
B185: =COUNTIF('Current Cadence'!D:D,DupeCheck!A185) -> 0
B186: =COUNTIF('Current Cadence'!D:D,DupeCheck!A186) -> 0
B187: =COUNTIF('Current Cadence'!D:D,DupeCheck!A187) -> 0
B188: =COUNTIF('Current Cadence'!D:D,DupeCheck!A188) -> 0
B189: =COUNTIF('Current Cadence'!D:D,DupeCheck!A189) -> 0
B190: =COUNTIF('Current Cadence'!D:D,DupeCheck!A190) -> 0
B191: =COUNTIF('Current Cadence'!D:D,DupeCheck!A191) -> 0
B192: =COUNTIF('Current Cadence'!D:D,DupeCheck!A192) -> 0
... B351: =COUNTIF('Current Cadence'!D:D,DupeCheck!A351) -> 0

Sheet ViewBeforeCopy

Sheet LiveCadenceBeforeCopy
A1: ITSS Cisco LoB | B1: Telkom Consumer | C1: Mining Indust&Health | D1: OPP133098 | E1: 33825197 | F1: 1691259.9 | G1: 1691259.9 | H1: 0.05 | I1: Commit | J1: 46174 | K1: FY 27 Q1 | L1: No | M1: Backlog Deal | N1: High | O1: checked | P1: johan Taljaard | Q1: Wimpie Pieterse | R1: OEM Service | S1: SFC Annual Payment
A2: ITSS Cisco LoB | B2: The Spar Group Ltd | C2: FSI & Retail | D2: OPP136919 | E2: 38123456 | F2: 4574814.7 | G2: 4574814.7 | H2: 0.12 | I2: Upside | J2: 46174 | K2: FY 27 Q1 | L2: No | M2: Upside Deal | N2: High | O2: checked | P2: Roan van Nieuwenhuizen | Q2: Wimpie Pieterse | R2: Software / Licence | S2: Need to move Licenses to another ORG to reduce the License limit. This is before we can create Cisco Meraki EA
A3: ITSS Cisco LoB | B3: Telkom Consumer | C3: Mining Indust&Health | D3: OPP147259 | E3: 21938052 | F3: 21938052 | G3: 2193805.2 | H3: 0.1 | I3: Upside | J3: 46327 | K3: FY 27 Q3 | L3: No | M3: Upside Deal | N3: Low | O3: checked | P3: Johan Taljaard | Q3: Wimpie Pieterse | R3: Product
A4: ITSS Cisco LoB | B4: Telkom Consumer | C4: Mining Indust&Health | D4: OPP135119/01 | E4: 15799289 | F4: 15799289 | G4: 1421936 | H4: 0.09 | I4: Upside | J4: 46327 | K4: FY 27 Q3 | L4: No | M4: Upside Deal | N4: Medium | O4: checked | P4: Johan Taljaard | Q4: Wimpie Pieterse | R4: Product | S4: EDD 154 days after order placement - Nutanix Expansion Value updated, Busy repricing will be resubmitted to Telkom
A5: ITSS Cisco LoB | B5: Openserve (Pty) Ltd | C5: Mining Indust&Health | D5: OPP145588 | E5: 13312345 | F5: 665617.25 | G5: 665617.25 | H5: 0.05 | I5: Upside | J5: 46174 | K5: FY 27 Q1 | L5: No | M5: Upside Deal | N5: High | O5: checked | P5: Johan Taljaard | Q5: Wimpie Pieterse | R5: OEM Service | S5: Opernserve Sweep Year 1 of 3
A6: ITSS Cisco LoB | B6: Discovery Central Services (Pty) Ltd | C6: FSI & Retail | D6: OPP147096 | E6: 30614619 | F6: 30614619 | G6: 1530730.9 | H6: 0.05 | I6: Upside | J6: 46235 | K6: FY 27 Q2 | L6: No | M6: Upside Deal | N6: Low | O6: checked | P6: Paul van Rooyen | Q6: Wimpie Pieterse | R6: Product | S6: RFQ - Network refresh
A7: ITSS Cisco LoB | B7: Nedbank Limited | C7: FSI & Retail | D7: OPP147252 | E7: 14378595 | F7: 862715.69 | G7: 862715.69 | H7: 0.06 | I7: Upside | J7: 46266 | K7: FY 27 Q2 | L7: No | M7: Upside Deal | N7: Low | O7: Checked | P7: Sean Royds | Q7: Wimpie Pieterse | R7: Product | S7: Budgetsry for Jac-Lou Wireless Guest Portal Business Case
A8: ITSS Cisco LoB | B8: Nedbank Limited | C8: FSI & Retail | D8: OPP147043 | E8: 5790700.2 | F8: 5790700.2 | G8: 347442.01 | H8: 0.06 | I8: Commit | J8: 46204 | K8: FY 27 Q2 | L8: No | M8: Backlog Deal | N8: High | P8: Sean Royds | Q8: Wimpie Pieterse | R8: Product | S8: EDD 16 July; Shuaib will push to add to NBV Jul signoff
A9: ITSS Cisco LoB | B9: Momentum Metropolitan Life Ltd Metropolitan | C9: FSI & Retail | D9: OPP142558 | E9: 5238762.6 | F9: 5238762.6 | G9: 628651.51 | H9: 0.12 | I9: Commit | J9: 46143 | K9: FY 27 Q1 | L9: Yes | M9: Backlog Deal | N9: High | O9: Checked | P9: Wandile Dlamini | Q9: Wimpie Pieterse | R9: Product | S9: EDD 196 days after order placement - New Rivonia branch
A10: ITSS Cisco LoB | B10: Sanlam Life Insurance Limited | C10: FSI & Retail | D10: OPP145900 | E10: 4059485.9 | F10: 4059485.9 | G10: 405948.59 | H10: 0.1 | I10: Commit | J10: 46235 | K10: FY 27 Q2 | L10: No | M10: Backlog Deal | N10: High | P10: Sean Royds | Q10: Wimpie Pieterse | R10: Product | S10: EDD 29 July 2026
A11: ITSS Cisco LoB | B11: Nedbank Limited | C11: FSI & Retail | D11: OPP146264 | E11: 3776766.7 | F11: 3776766.7 | G11: 226606 | H11: 0.06 | I11: Commit | J11: 46174 | K11: FY 27 Q1 | L11: No | M11: Backlog Deal | N11: High | P11: Sean Royds | Q11: Wimpie Pieterse | R11: Product | S11: Partial Invoice Chassis in May, Awaiting SFP's due Jun (EDD 29 May 2026)
A12: ITSS Cisco LoB | B12: Woolworths (Pty) Limited | C12: FSI & Retail | D12: OPP125614 | E12: 3549755 | F12: 3532442.3 | G12: 353244.23 | H12: 0.1 | I12: Commit | J12: 46174 | K12: FY 27 Q1 | L12: No | M12: Backlog Deal | N12: High | P12: Olden Pieterse | Q12: Wimpie Pieterse | R12: Product | S12: EDD 196 days from order - DC3 refresh
A13: ITSS Cisco LoB | B13: The Spar Group Ltd | C13: FSI & Retail | D13: OPP147253 | E13: 2665953 | F13: 2665953 | G13: 319914.36 | H13: 0.12 | I13: Commit | J13: 46235 | K13: FY 27 Q2 | L13: No | M13: Backlog Deal | N13: High | P13: Olden Pieterse | Q13: Wimpie Pieterse | R13: Product | S13: EDD 18 June - VC equipment
A14: ITSS Cisco LoB | B14: Sanlam Life Insurance Limited | C14: FSI & Retail | D14: OPP145570 | E14: 1289968.4 | F14: 1289968.4 | G14: 128996.84 | H14: 0.1 | I14: Commit | J14: 46174 | K14: FY 27 Q1 | L14: No | M14: Backlog Deal | N14: High | P14: Sean Royds | Q14: Wimpie Pieterse | R14: Product | S14: EDD 3 June 2026 - Additional Line Card modules
A15: ITSS Cisco LoB | B15: Pioneer Foods (Pty) Ltd | C15: FSI & Retail | D15: OPP131208/04 | E15: 1104339 | F15: 1104339 | G15: 110433.9 | H15: 0.1 | I15: Commit | J15: 46388 | K15: FY 27 Q4 | L15: No | M15: Backlog Deal | N15: High | P15: Olden Pieterse | Q15: Wimpie Pieterse | R15: Product | S15: EDD May - Aeroton Bakery - order received
A16: ITSS Cisco LoB | B16: Momentum Group-Wide Services (Pty) Ltd | C16: FSI & Retail | D16: OPP113848/04 | E16: 2326283 | F16: 232628.3 | G16: 232628.3 | H16: 0.1 | I16: Commit | J16: 46266 | K16: FY 27 Q2 | L16: No | M16: Backlog Deal | N16: High | O16: Checked | P16: Paul van Rooyen | Q16: Wimpie Pieterse | R16: Software / Licence | S16: Stanlib APP-D year 2/3
A17: ITSS Cisco LoB | B17: The Spar Group Ltd | C17: FSI & Retail | D17: OPP147073 | E17: 1056330 | F17: 1056330 | G17: 126759.6 | H17: 0.12 | I17: Commit | J17: 46143 | K17: FY 27 Q1 | L17: Yes | M17: Backlog Deal | N17: High | P17: Olden Pieterse | Q17: Wimpie Pieterse | R17: Product | S17: EDD 4 May - 200 x MX67
A18: ITSS Cisco LoB | B18: Tiger Consumer Brands Limited | C18: FSI & Retail | D18: OPP146069 | E18: 1572349.9 | F18: 1572349.9 | G18: 125787.99 | H18: 0.08 | I18: Commit | J18: 46204 | K18: FY 27 Q2 | L18: No | M18: Backlog Deal | N18: High | P18: Nowell Duze | Q18: Wimpie Pieterse | R18: Product
A19: ITSS Cisco LoB | B19: Tiger Consumer Brands Limited | C19: FSI & Retail | D19: OPP138466 | E19: 10753040 | F19: 860243.23 | G19: 860243.23 | H19: 0.08 | I19: Upside | J19: 46204 | K19: FY 27 Q2 | L19: No | M19: Upside Deal | N19: Low | P19: Nowell Duze | Q19: Wimpie Pieterse | R19: Product | S19: Quote refreshed on the 18th of May. Vblock DC switches
A20: ITSS Cisco LoB | B20: Tiger Consumer Brands Limited | C20: FSI & Retail | D20: OPP146660 | E20: 5301769.3 | F20: 5301769.3 | G20: 424141.55 | H20: 0.08 | I20: Upside | J20: 46204 | K20: FY 27 Q2 | L20: No | M20: Upside Deal | N20: Low | P20: Nowell Duze | Q20: Wimpie Pieterse | R20: Product | S20: Bafo Pricing submitted on the 22nd May 2026
A21: ITSS Cisco LoB | B21: Sanlam Life Insurance Limited | C21: FSI & Retail | D21: OPP137867 | E21: 4963898 | F21: 4963898 | G21: 496389.8 | H21: 0.1 | I21: Upside | J21: 46235 | K21: FY 27 Q2 | L21: No | M21: Upside Deal | N21: Medium | P21: Sean Royds | Q21: Wimpie Pieterse | R21: Product | S21: EDD 56 days after order placement - Assupol SD-WAN Routers
A22: ITSS Cisco LoB | B22: Pioneer Foods (Pty) Ltd | C22: FSI & Retail | D22: OPP136579/03 | E22: 655608 | F22: 655608 | G22: 65560.8 | H22: 0.1 | I22: Commit | J22: 46388 | K22: FY 27 Q4 | L22: No | M22: Backlog Deal | N22: High | P22: Olden Pieterse | Q22: Wimpie Pieterse | R22: Product | S22: EDD May - SAD Upington - order received
A23: ITSS Cisco LoB | B23: Sanlam | C23: FSI & Retail | D23: OPP146115 | E23: 3926119.1 | F23: 3926119.1 | G23: 392611.91 | H23: 0.1 | I23: Upside | J23: 46235 | K23: FY 27 Q2 | L23: No | M23: Upside Deal | N23: Medium | O23: Checked | P23: Sean Royds | Q23: Wimpie Pieterse | R23: Product | S23: Sanlam reviewing to potentially bundle deals together
A24: ITSS Cisco LoB | B24: MR PRICE | C24: FSI & Retail | D24: OPP147804 | E24: 3083916.6 | F24: 308391.66 | G24: 308391.66 | H24: 0.1 | I24: Upside | J24: 46204 | K24: FY 27 Q2 | L24: No | M24: Upside Deal | N24: Low | P24: Olden Pieterse | Q24: Wimpie Pieterse | R24: Product | S24: Submitted pricing to Mr Price: Speculation at this point
A25: ITSS Cisco LoB | B25: Investec Bank Limited | C25: FSI & Retail | D25: OPP139009 | E25: 2849544.4 | F25: 2849544.4 | G25: 341945.33 | H25: 0.12 | I25: Upside | J25: 46235 | K25: FY 27 Q2 | L25: No | M25: Upside Deal | N25: Low | P25: Sean Royds | Q25: Wimpie Pieterse | R25: Product | S25: EDD 42 days after order placement - ACI hardware replacement
